<?xml version="1.0" encoding="UTF-8"?>
<!-- Generated by org.testng.reporters.JUnitReportReporter -->
<testsuite hostname="DESKTOP-21OGGBD" failures="4" tests="16" name="testcases.LoginTest" time="80.679" errors="0" timestamp="2023-09-18T11:48:09 EDT" skipped="0">
  <testcase classname="testcases.LoginTest" name="openSignInPage" time="3.522"/>
  <testcase classname="testcases.LoginTest" name="validateCheckBox" time="3.787"/>
  <testcase classname="testcases.LoginTest" name="openCourseGallery" time="7.128">
    <failure message="expected [Choose your area of expertise] but found [Business Analyst]" type="java.lang.AssertionError">
      <![CDATA[java.lang.AssertionError: expected [Choose your area of expertise] but found [Business Analyst]
at org.testng.Assert.fail(Assert.java:111)
at org.testng.Assert.failNotEquals(Assert.java:1578)
at org.testng.Assert.assertEqualsImpl(Assert.java:150)
at org.testng.Assert.assertEquals(Assert.java:132)
at org.testng.Assert.assertEquals(Assert.java:656)
at org.testng.Assert.assertEquals(Assert.java:666)
at pageobject.CourseGalleryPage.hardAsserts(CourseGalleryPage.java:41)
at testcases.LoginTest.openCourseGallery(LoginTest.java:25)
at java.base/jdk.internal.reflect.DirectMethodHandleAccessor.invoke(DirectMethodHandleAccessor.java:104)
at java.base/java.lang.reflect.Method.invoke(Method.java:578)
at org.testng.internal.invokers.MethodInvocationHelper.invokeMethod(MethodInvocationHelper.java:139)
at org.testng.internal.invokers.TestInvoker.invokeMethod(TestInvoker.java:664)
at org.testng.internal.invokers.TestInvoker.invokeTestMethod(TestInvoker.java:227)
at org.testng.internal.invokers.MethodRunner.runInSequence(MethodRunner.java:50)
at org.testng.internal.invokers.TestInvoker$MethodInvocationAgent.invoke(TestInvoker.java:957)
at org.testng.internal.invokers.TestInvoker.invokeTestMethods(TestInvoker.java:200)
at org.testng.internal.invokers.TestMethodWorker.invokeTestMethods(TestMethodWorker.java:148)
at org.testng.internal.invokers.TestMethodWorker.run(TestMethodWorker.java:128)
at java.base/java.util.ArrayList.forEach(ArrayList.java:1511)
at org.testng.TestRunner.privateRun(TestRunner.java:848)
at org.testng.TestRunner.run(TestRunner.java:621)
at org.testng.SuiteRunner.runTest(SuiteRunner.java:443)
at org.testng.SuiteRunner.runSequentially(SuiteRunner.java:437)
at org.testng.SuiteRunner.privateRun(SuiteRunner.java:397)
at org.testng.SuiteRunner.run(SuiteRunner.java:336)
at org.testng.SuiteRunnerWorker.runSuite(SuiteRunnerWorker.java:52)
at org.testng.SuiteRunnerWorker.run(SuiteRunnerWorker.java:95)
at org.testng.TestNG.runSuitesSequentially(TestNG.java:1280)
at org.testng.TestNG.runSuitesLocally(TestNG.java:1200)
at org.testng.TestNG.runSuites(TestNG.java:1114)
at org.testng.TestNG.run(TestNG.java:1082)
at org.apache.maven.surefire.testng.TestNGExecutor.run(TestNGExecutor.java:283)
at org.apache.maven.surefire.testng.TestNGXmlTestSuite.execute(TestNGXmlTestSuite.java:75)
at org.apache.maven.surefire.testng.TestNGProvider.invoke(TestNGProvider.java:120)
at org.apache.maven.surefire.booter.ForkedBooter.invokeProviderInSameClassLoader(ForkedBooter.java:384)
at org.apache.maven.surefire.booter.ForkedBooter.runSuitesInProcess(ForkedBooter.java:345)
at org.apache.maven.surefire.booter.ForkedBooter.execute(ForkedBooter.java:126)
at org.apache.maven.surefire.booter.ForkedBooter.main(ForkedBooter.java:418)
]]>
    </failure>
  </testcase> <!-- openCourseGallery -->
  <testcase classname="testcases.LoginTest" name="enterInvalidEmailLogin" time="5.317"/>
  <testcase classname="testcases.LoginTest" name="enterInvalidEmailLogin" time="5.563"/>
  <testcase classname="testcases.LoginTest" name="startDriver" time="2.920"/>
  <testcase classname="testcases.LoginTest" name="validateEmailPasswordLogin" time="4.117"/>
  <testcase classname="testcases.LoginTest" name="startDriver" time="2.799"/>
  <testcase classname="testcases.LoginTest" name="openCourseGallery" time="3.677">
    <failure message="expected [Choose your area of expertise] but found [Business Analyst]" type="java.lang.AssertionError">
      <![CDATA[java.lang.AssertionError: expected [Choose your area of expertise] but found [Business Analyst]
at org.testng.Assert.fail(Assert.java:111)
at org.testng.Assert.failNotEquals(Assert.java:1578)
at org.testng.Assert.assertEqualsImpl(Assert.java:150)
at org.testng.Assert.assertEquals(Assert.java:132)
at org.testng.Assert.assertEquals(Assert.java:656)
at org.testng.Assert.assertEquals(Assert.java:666)
at pageobject.CourseGalleryPage.hardAsserts(CourseGalleryPage.java:41)
at testcases.LoginTest.openCourseGallery(LoginTest.java:25)
at java.base/jdk.internal.reflect.DirectMethodHandleAccessor.invoke(DirectMethodHandleAccessor.java:104)
at java.base/java.lang.reflect.Method.invoke(Method.java:578)
at org.testng.internal.invokers.MethodInvocationHelper.invokeMethod(MethodInvocationHelper.java:139)
at org.testng.internal.invokers.TestInvoker.invokeMethod(TestInvoker.java:664)
at org.testng.internal.invokers.TestInvoker.invokeTestMethod(TestInvoker.java:227)
at org.testng.internal.invokers.MethodRunner.runInSequence(MethodRunner.java:50)
at org.testng.internal.invokers.TestInvoker$MethodInvocationAgent.invoke(TestInvoker.java:957)
at org.testng.internal.invokers.TestInvoker.invokeTestMethods(TestInvoker.java:200)
at org.testng.internal.invokers.TestMethodWorker.invokeTestMethods(TestMethodWorker.java:148)
at org.testng.internal.invokers.TestMethodWorker.run(TestMethodWorker.java:128)
at java.base/java.util.ArrayList.forEach(ArrayList.java:1511)
at org.testng.TestRunner.privateRun(TestRunner.java:848)
at org.testng.TestRunner.run(TestRunner.java:621)
at org.testng.SuiteRunner.runTest(SuiteRunner.java:443)
at org.testng.SuiteRunner.runSequentially(SuiteRunner.java:437)
at org.testng.SuiteRunner.privateRun(SuiteRunner.java:397)
at org.testng.SuiteRunner.run(SuiteRunner.java:336)
at org.testng.SuiteRunnerWorker.runSuite(SuiteRunnerWorker.java:52)
at org.testng.SuiteRunnerWorker.run(SuiteRunnerWorker.java:95)
at org.testng.TestNG.runSuitesSequentially(TestNG.java:1280)
at org.testng.TestNG.runSuitesLocally(TestNG.java:1200)
at org.testng.TestNG.runSuites(TestNG.java:1114)
at org.testng.TestNG.run(TestNG.java:1082)
at org.apache.maven.surefire.testng.TestNGExecutor.run(TestNGExecutor.java:283)
at org.apache.maven.surefire.testng.TestNGXmlTestSuite.execute(TestNGXmlTestSuite.java:75)
at org.apache.maven.surefire.testng.TestNGProvider.invoke(TestNGProvider.java:120)
at org.apache.maven.surefire.booter.ForkedBooter.invokeProviderInSameClassLoader(ForkedBooter.java:384)
at org.apache.maven.surefire.booter.ForkedBooter.runSuitesInProcess(ForkedBooter.java:345)
at org.apache.maven.surefire.booter.ForkedBooter.execute(ForkedBooter.java:126)
at org.apache.maven.surefire.booter.ForkedBooter.main(ForkedBooter.java:418)
]]>
    </failure>
  </testcase> <!-- openCourseGallery -->
  <testcase classname="testcases.LoginTest" name="validateError" time="8.880"/>
  <testcase classname="testcases.LoginTest" name="validateError" time="9.608"/>
  <testcase classname="testcases.LoginTest" name="validateCheckBox" time="3.934"/>
  <testcase classname="testcases.LoginTest" name="openSignUpPage" time="4.001">
    <failure message="The following asserts failed:
	expected [Already have] but found [Already have an account? Log In],
	expected [8] but found [14],
	expected [Email address] but found [Email]" type="java.lang.AssertionError">
      <![CDATA[java.lang.AssertionError: The following asserts failed:
expected [Already have] but found [Already have an account? Log In],
expected [8] but found [14],
expected [Email address] but found [Email]
at org.testng.asserts.SoftAssert.assertAll(SoftAssert.java:46)
at org.testng.asserts.SoftAssert.assertAll(SoftAssert.java:30)
at pageobject.SignUpPage.softAsserts(SignUpPage.java:60)
at testcases.LoginTest.openSignUpPage(LoginTest.java:43)
at java.base/jdk.internal.reflect.DirectMethodHandleAccessor.invoke(DirectMethodHandleAccessor.java:104)
at java.base/java.lang.reflect.Method.invoke(Method.java:578)
at org.testng.internal.invokers.MethodInvocationHelper.invokeMethod(MethodInvocationHelper.java:139)
at org.testng.internal.invokers.TestInvoker.invokeMethod(TestInvoker.java:664)
at org.testng.internal.invokers.TestInvoker.invokeTestMethod(TestInvoker.java:227)
at org.testng.internal.invokers.MethodRunner.runInSequence(MethodRunner.java:50)
at org.testng.internal.invokers.TestInvoker$MethodInvocationAgent.invoke(TestInvoker.java:957)
at org.testng.internal.invokers.TestInvoker.invokeTestMethods(TestInvoker.java:200)
at org.testng.internal.invokers.TestMethodWorker.invokeTestMethods(TestMethodWorker.java:148)
at org.testng.internal.invokers.TestMethodWorker.run(TestMethodWorker.java:128)
at java.base/java.util.ArrayList.forEach(ArrayList.java:1511)
at org.testng.TestRunner.privateRun(TestRunner.java:848)
at org.testng.TestRunner.run(TestRunner.java:621)
at org.testng.SuiteRunner.runTest(SuiteRunner.java:443)
at org.testng.SuiteRunner.runSequentially(SuiteRunner.java:437)
at org.testng.SuiteRunner.privateRun(SuiteRunner.java:397)
at org.testng.SuiteRunner.run(SuiteRunner.java:336)
at org.testng.SuiteRunnerWorker.runSuite(SuiteRunnerWorker.java:52)
at org.testng.SuiteRunnerWorker.run(SuiteRunnerWorker.java:95)
at org.testng.TestNG.runSuitesSequentially(TestNG.java:1280)
at org.testng.TestNG.runSuitesLocally(TestNG.java:1200)
at org.testng.TestNG.runSuites(TestNG.java:1114)
at org.testng.TestNG.run(TestNG.java:1082)
at org.apache.maven.surefire.testng.TestNGExecutor.run(TestNGExecutor.java:283)
at org.apache.maven.surefire.testng.TestNGXmlTestSuite.execute(TestNGXmlTestSuite.java:75)
at org.apache.maven.surefire.testng.TestNGProvider.invoke(TestNGProvider.java:120)
at org.apache.maven.surefire.booter.ForkedBooter.invokeProviderInSameClassLoader(ForkedBooter.java:384)
at org.apache.maven.surefire.booter.ForkedBooter.runSuitesInProcess(ForkedBooter.java:345)
at org.apache.maven.surefire.booter.ForkedBooter.execute(ForkedBooter.java:126)
at org.apache.maven.surefire.booter.ForkedBooter.main(ForkedBooter.java:418)
]]>
    </failure>
  </testcase> <!-- openSignUpPage -->
  <testcase classname="testcases.LoginTest" name="validateEmailPasswordLogin" time="8.266"/>
  <testcase classname="testcases.LoginTest" name="openSignInPage" time="3.359"/>
  <testcase classname="testcases.LoginTest" name="openSignUpPage" time="3.801">
    <failure message="The following asserts failed:
	expected [Already have] but found [Already have an account? Log In],
	expected [8] but found [14],
	expected [Email address] but found [Email]" type="java.lang.AssertionError">
      <![CDATA[java.lang.AssertionError: The following asserts failed:
expected [Already have] but found [Already have an account? Log In],
expected [8] but found [14],
expected [Email address] but found [Email]
at org.testng.asserts.SoftAssert.assertAll(SoftAssert.java:46)
at org.testng.asserts.SoftAssert.assertAll(SoftAssert.java:30)
at pageobject.SignUpPage.softAsserts(SignUpPage.java:60)
at testcases.LoginTest.openSignUpPage(LoginTest.java:43)
at java.base/jdk.internal.reflect.DirectMethodHandleAccessor.invoke(DirectMethodHandleAccessor.java:104)
at java.base/java.lang.reflect.Method.invoke(Method.java:578)
at org.testng.internal.invokers.MethodInvocationHelper.invokeMethod(MethodInvocationHelper.java:139)
at org.testng.internal.invokers.TestInvoker.invokeMethod(TestInvoker.java:664)
at org.testng.internal.invokers.TestInvoker.invokeTestMethod(TestInvoker.java:227)
at org.testng.internal.invokers.MethodRunner.runInSequence(MethodRunner.java:50)
at org.testng.internal.invokers.TestInvoker$MethodInvocationAgent.invoke(TestInvoker.java:957)
at org.testng.internal.invokers.TestInvoker.invokeTestMethods(TestInvoker.java:200)
at org.testng.internal.invokers.TestMethodWorker.invokeTestMethods(TestMethodWorker.java:148)
at org.testng.internal.invokers.TestMethodWorker.run(TestMethodWorker.java:128)
at java.base/java.util.ArrayList.forEach(ArrayList.java:1511)
at org.testng.TestRunner.privateRun(TestRunner.java:848)
at org.testng.TestRunner.run(TestRunner.java:621)
at org.testng.SuiteRunner.runTest(SuiteRunner.java:443)
at org.testng.SuiteRunner.runSequentially(SuiteRunner.java:437)
at org.testng.SuiteRunner.privateRun(SuiteRunner.java:397)
at org.testng.SuiteRunner.run(SuiteRunner.java:336)
at org.testng.SuiteRunnerWorker.runSuite(SuiteRunnerWorker.java:52)
at org.testng.SuiteRunnerWorker.run(SuiteRunnerWorker.java:95)
at org.testng.TestNG.runSuitesSequentially(TestNG.java:1280)
at org.testng.TestNG.runSuitesLocally(TestNG.java:1200)
at org.testng.TestNG.runSuites(TestNG.java:1114)
at org.testng.TestNG.run(TestNG.java:1082)
at org.apache.maven.surefire.testng.TestNGExecutor.run(TestNGExecutor.java:283)
at org.apache.maven.surefire.testng.TestNGXmlTestSuite.execute(TestNGXmlTestSuite.java:75)
at org.apache.maven.surefire.testng.TestNGProvider.invoke(TestNGProvider.java:120)
at org.apache.maven.surefire.booter.ForkedBooter.invokeProviderInSameClassLoader(ForkedBooter.java:384)
at org.apache.maven.surefire.booter.ForkedBooter.runSuitesInProcess(ForkedBooter.java:345)
at org.apache.maven.surefire.booter.ForkedBooter.execute(ForkedBooter.java:126)
at org.apache.maven.surefire.booter.ForkedBooter.main(ForkedBooter.java:418)
]]>
    </failure>
  </testcase> <!-- openSignUpPage -->
</testsuite> <!-- testcases.LoginTest -->
